<?xml version="1.0" encoding="utf-8"?>
<!-- This URDF was automatically created by SolidWorks to URDF Exporter! Originally created by Stephen Brawner (brawner@gmail.com) 
     Commit Version: 1.6.0-4-g7f85cfe  Build Version: 1.6.7995.38578
     For more information, please see http://wiki.ros.org/sw_urdf_exporter -->
<robot
  name="khung xe (1).sldasm">
  <link
    name="base_link">
    <inertial>
      <origin
        xyz="-0.0016911 0.060515 -0.0040379"
        rpy="0 0 0" />
      <mass
        value="5.4519" />
      <inertia
        ixx="0.019725"
        ixy="-0.00045193"
        ixz="1.0484E-08"
        iyy="0.03498"
        iyz="1.3507E-06"
        izz="0.022321" />
    </inertial>
    <visual>
      <origin
        xyz="0 0 0"
        rpy="0 0 0" />
      <geometry>
        <mesh
          filename="package://khung xe (1).sldasm/meshes/base_link.STL" />
      </geometry>
      <material
        name="">
        <color
          rgba="1 1 1 1" />
      </material>
    </visual>
    <collision>
      <origin
        xyz="0 0 0"
        rpy="0 0 0" />
      <geometry>
        <mesh
          filename="package://khung xe (1).sldasm/meshes/base_link.STL" />
      </geometry>
    </collision>
  </link>
  <link
    name="left_link">
    <inertial>
      <origin
        xyz="-8.88180099481439E-07 2.77555756156289E-17 0.0203827214868579"
        rpy="0 0 0" />
      <mass
        value="0.968975774829785" />
      <inertia
        ixx="0.00170115560343656"
        ixy="1.88539788642714E-18"
        ixz="1.82218282057685E-09"
        iyy="0.00170115056996547"
        iyz="4.80558046232636E-18"
        izz="0.00288276759907122" />
    </inertial>
    <visual>
      <origin
        xyz="0 0 0"
        rpy="0 0 0" />
      <geometry>
        <mesh
          filename="package://khung xe (1).sldasm/meshes/left_link.STL" />
      </geometry>
      <material
        name="">
        <color
          rgba="0.792156862745098 0.819607843137255 0.933333333333333 1" />
      </material>
    </visual>
    <collision>
      <origin
        xyz="0 0 0"
        rpy="0 0 0" />
      <geometry>
        <mesh
          filename="package://khung xe (1).sldasm/meshes/left_link.STL" />
      </geometry>
    </collision>
  </link>
  <joint
    name="left_link"
    type="continuous">
    <origin
      xyz="-0.00166943518023849 0.0202499999999948 -0.213138302026856"
      rpy="0 0 0" />
    <parent
      link="base_link" />
    <child
      link="left_link" />
    <axis
      xyz="0 0 1" />
  </joint>
  <link
    name="right_link">
    <inertial>
      <origin
        xyz="0.000131413454829796 8.65973959207622E-15 -0.0203827214868589"
        rpy="0 0 0" />
      <mass
        value="0.968975774829785" />
      <inertia
        ixx="0.00170115560343656"
        ixy="-1.97842337708994E-18"
        ixz="1.82218282863064E-09"
        iyy="0.00170115056996547"
        iyz="-1.27392630695615E-19"
        izz="0.00288276759907123" />
    </inertial>
    <visual>
      <origin
        xyz="0 0 0"
        rpy="0 0 0" />
      <geometry>
        <mesh
          filename="package://khung xe (1).sldasm/meshes/right_link.STL" />
      </geometry>
      <material
        name="">
        <color
          rgba="0.792156862745098 0.819607843137255 0.933333333333333 1" />
      </material>
    </visual>
    <collision>
      <origin
        xyz="0 0 0"
        rpy="0 0 0" />
      <geometry>
        <mesh
          filename="package://khung xe (1).sldasm/meshes/right_link.STL" />
      </geometry>
    </collision>
  </link>
  <joint
    name="right_link"
    type="continuous">
    <origin
      xyz="-0.00166943518023559 0.0202499999999948 0.204334897973151"
      rpy="0 0 0" />
    <parent
      link="base_link" />
    <child
      link="right_link" />
    <axis
      xyz="0 0 -1" />
  </joint>
</robot>